Workbook

Sheet Clientes
A1: Fecha | B1: Infor Code | C1: Customer | D1: Current | E1: 1 - 90 | F1: 91 - 180 | G1: 181 - 270 | H1: 271-360 | I1: > 360 | J1: TOTAL
A2: 45322 | B2: =IFERROR(IF(VLOOKUP(C2,Hoja1!$B$1:$C$6191,2,0)="",_xlfn.XLOOKUP(C2,Hoja1!$B$2:$B$6191,Hoja1!$A$2:$A$6191),VLOOKUP(C2,Hoja1!$B$1:$C$6191,2,0)),"No esta en Infor") -> NAC1448 | C2: UNFI | D2: 150649.83 | E2: 6569 | F2: 15178.65 | G2: 5215.39 | H2: 3031.04 | I2: 2514 | J2: 183157.91
A3: 45322 | B3: =IFERROR(IF(VLOOKUP(C3,Hoja1!$B$1:$C$6191,2,0)="",_xlfn.XLOOKUP(C3,Hoja1!$B$2:$B$6191,Hoja1!$A$2:$A$6191),VLOOKUP(C3,Hoja1!$B$1:$C$6191,2,0)),"No esta en Infor") -> NAC0456 | C3: 1-800Flowers.com | D3: 2144.32 | E3: 0 | F3: 0 | G3: 1450.95 | H3: 0 | I3: 0 | J3: 3595.27
A4: 45322 | B4: =IFERROR(IF(VLOOKUP(C4,Hoja1!$B$1:$C$6191,2,0)="",_xlfn.XLOOKUP(C4,Hoja1!$B$2:$B$6191,Hoja1!$A$2:$A$6191),VLOOKUP(C4,Hoja1!$B$1:$C$6191,2,0)),"No esta en Infor") -> NAC0476 | C4: Ahold USA | D4: 334342.18 | E4: 1334.19 | F4: 10864.81 | G4: -212 | H4: 0 | I4: 0 | J4: 346329.18
A5: 45322 | B5: =IFERROR(IF(VLOOKUP(C5,Hoja1!$B$1:$C$6191,2,0)="",_xlfn.XLOOKUP(C5,Hoja1!$B$2:$B$6191,Hoja1!$A$2:$A$6191),VLOOKUP(C5,Hoja1!$B$1:$C$6191,2,0)),"No esta en Infor") -> NAC0483 | C5: Albertsons | D5: 3686.68 | E5: 4016.78 | F5: 1402.04 | G5: 5405.25 | H5: 12409.43 | I5: 0 | J5: 26920.18
A6: 45322 | B6: =IFERROR(IF(VLOOKUP(C6,Hoja1!$B$1:$C$6191,2,0)="",_xlfn.XLOOKUP(C6,Hoja1!$B$2:$B$6191,Hoja1!$A$2:$A$6191),VLOOKUP(C6,Hoja1!$B$1:$C$6191,2,0)),"No esta en Infor") -> NAC0537 | C6: Armstrong Garden Centers, Inc | D6: 11861.77 | E6: 0 | F6: 713.36 | G6: 0 | H6: 0 | I6: 0 | J6: 12575.13
A7: 45322 | B7: =IFERROR(IF(VLOOKUP(C7,Hoja1!$B$1:$C$6191,2,0)="",_xlfn.XLOOKUP(C7,Hoja1!$B$2:$B$6191,Hoja1!$A$2:$A$6191),VLOOKUP(C7,Hoja1!$B$1:$C$6191,2,0)),"No esta en Infor") -> NAC0556 | C7: Battlefield | D7: 0 | E7: 2983 | F7: 2606.13 | G7: 0 | H7: 0 | I7: 0 | J7: 5589.13
A8: 45322 | B8: =IFERROR(IF(VLOOKUP(C8,Hoja1!$B$1:$C$6191,2,0)="",_xlfn.XLOOKUP(C8,Hoja1!$B$2:$B$6191,Hoja1!$A$2:$A$6191),VLOOKUP(C8,Hoja1!$B$1:$C$6191,2,0)),"No esta en Infor") -> NAC0573 | C8: BFG SUPPLY COMPANY | D8: 2987.52 | E8: 1226.68 | F8: 2666.33 | G8: 0 | H8: 0 | I8: 0 | J8: 6880.53
A9: 45322 | B9: =IFERROR(IF(VLOOKUP(C9,Hoja1!$B$1:$C$6191,2,0)="",_xlfn.XLOOKUP(C9,Hoja1!$B$2:$B$6191,Hoja1!$A$2:$A$6191),VLOOKUP(C9,Hoja1!$B$1:$C$6191,2,0)),"No esta en Infor") -> NAC0597 | C9: The Brenmar Inc. | D9: 0 | E9: 804.56 | F9: 488.2 | G9: 0 | H9: 0 | I9: 0 | J9: 1292.76
A10: 45322 | B10: =IFERROR(IF(VLOOKUP(C10,Hoja1!$B$1:$C$6191,2,0)="",_xlfn.XLOOKUP(C10,Hoja1!$B$2:$B$6191,Hoja1!$A$2:$A$6191),VLOOKUP(C10,Hoja1!$B$1:$C$6191,2,0)),"No esta en Infor") -> NAC0610 | C10: BUNZL | D10: 60709.67 | E10: 24445.89 | F10: 242 | G10: 0 | H10: 0 | I10: 0 | J10: 85397.56
A11: 45322 | B11: =IFERROR(IF(VLOOKUP(C11,Hoja1!$B$1:$C$6191,2,0)="",_xlfn.XLOOKUP(C11,Hoja1!$B$2:$B$6191,Hoja1!$A$2:$A$6191),VLOOKUP(C11,Hoja1!$B$1:$C$6191,2,0)),"No esta en Infor") -> CAN0006 | C11: Burnaby Lake Greenhouses | D11: 29353.71 | E11: 71965.9 | F11: 46267.63 | G11: 0 | H11: 0 | I11: 0 | J11: 147587.24
A12: 45322 | B12: =IFERROR(IF(VLOOKUP(C12,Hoja1!$B$1:$C$6191,2,0)="",_xlfn.XLOOKUP(C12,Hoja1!$B$2:$B$6191,Hoja1!$A$2:$A$6191),VLOOKUP(C12,Hoja1!$B$1:$C$6191,2,0)),"No esta en Infor") -> NAC0641 | C12: CHOATE NURSERY | D12: 0 | E12: 0 | F12: 363.64 | G12: 0 | H12: 0 | I12: 0 | J12: 363.64
A13: 45322 | B13: =IFERROR(IF(VLOOKUP(C13,Hoja1!$B$1:$C$6191,2,0)="",_xlfn.XLOOKUP(C13,Hoja1!$B$2:$B$6191,Hoja1!$A$2:$A$6191),VLOOKUP(C13,Hoja1!$B$1:$C$6191,2,0)),"No esta en Infor") -> NAC0662 | C13: Colony Florist | D13: 0 | E13: 0 | F13: 633.22 | G13: 0 | H13: 0 | I13: 0 | J13: 633.22
... A2617: 45535 | B2617: =IFERROR(IF(VLOOKUP(C2617,Hoja1!$B$1:$C$6191,2,0)="",_xlfn.XLOOKUP(C2617,Hoja1!$B$2:$B$6191,Hoja1!$A$2:$A$6191),VLOOKUP(C2617,Hoja1!$B$1:$C$6191,2,0)),"No esta en Infor") -> NAC1539 | C2617: Young's Plant Farm, Inc | D2617: 28844.4 | E2617: 0 | F2617: 0 | G2617: -5517 | H2617: -7.8 | I2617: 0 | J2617: 23319.6
A2618: 45565 | B2618: =IFERROR(IF(VLOOKUP(C2618,Hoja1!$B$1:$C$6191,2,0)="",_xlfn.XLOOKUP(C2618,Hoja1!$B$2:$B$6191,Hoja1!$A$2:$A$6191),VLOOKUP(C2618,Hoja1!$B$1:$C$6191,2,0)),"No esta en Infor") -> NAC0476 | C2618: Ahold USA | D2618: 110967.93 | F2618: 774.08 | G2618: 2250 | H2618: -345.39 | I2618: 0 | J2618: =SUM(D2618:I2618) -> 113646.62
A2619: 45565 | B2619: =IFERROR(IF(VLOOKUP(C2619,Hoja1!$B$1:$C$6191,2,0)="",_xlfn.XLOOKUP(C2619,Hoja1!$B$2:$B$6191,Hoja1!$A$2:$A$6191),VLOOKUP(C2619,Hoja1!$B$1:$C$6191,2,0)),"No esta en Infor") -> NAC0483 | C2619: Albertsons | D2619: -146.83 | F2619: 0 | G2619: 358.94 | H2619: 0 | I2619: 3835.58 | J2619: =SUM(D2619:I2619) -> 4047.69
A2620: 45565 | B2620: =IFERROR(IF(VLOOKUP(C2620,Hoja1!$B$1:$C$6191,2,0)="",_xlfn.XLOOKUP(C2620,Hoja1!$B$2:$B$6191,Hoja1!$A$2:$A$6191),VLOOKUP(C2620,Hoja1!$B$1:$C$6191,2,0)),"No esta en Infor") -> CAN0002 | C2620: Bayview Flowers | D2620: 3588.03 | F2620: 0 | G2620: -804.19 | H2620: 249.72 | I2620: 0 | J2620: =SUM(D2620:I2620) -> 3033.56
A2621: 45565 | B2621: =IFERROR(IF(VLOOKUP(C2621,Hoja1!$B$1:$C$6191,2,0)="",_xlfn.XLOOKUP(C2621,Hoja1!$B$2:$B$6191,Hoja1!$A$2:$A$6191),VLOOKUP(C2621,Hoja1!$B$1:$C$6191,2,0)),"No esta en Infor") -> NAC0573 | C2621: BFG SUPPLY COMPANY | D2621: 21638.03 | F2621: 0 | G2621: 0 | H2621: 193.5 | I2621: 90 | J2621: =SUM(D2621:I2621) -> 21921.53
A2622: 45565 | B2622: =IFERROR(IF(VLOOKUP(C2622,Hoja1!$B$1:$C$6191,2,0)="",_xlfn.XLOOKUP(C2622,Hoja1!$B$2:$B$6191,Hoja1!$A$2:$A$6191),VLOOKUP(C2622,Hoja1!$B$1:$C$6191,2,0)),"No esta en Infor") -> CAN0005 | C2622: Bloomstar Bouquet | D2622: 117061.01 | F2622: 0 | G2622: 0 | H2622: 10260 | I2622: 0 | J2622: =SUM(D2622:I2622) -> 127321.01
A2623: 45565 | B2623: =IFERROR(IF(VLOOKUP(C2623,Hoja1!$B$1:$C$6191,2,0)="",_xlfn.XLOOKUP(C2623,Hoja1!$B$2:$B$6191,Hoja1!$A$2:$A$6191),VLOOKUP(C2623,Hoja1!$B$1:$C$6191,2,0)),"No esta en Infor") -> NAC0614 | C2623: C&S Wholesale Grocers | D2623: 8020 | F2623: 150 | G2623: 0 | H2623: 0 | I2623: 0 | J2623: =SUM(D2623:I2623) -> 8170
A2624: 45565 | B2624: =IFERROR(IF(VLOOKUP(C2624,Hoja1!$B$1:$C$6191,2,0)="",_xlfn.XLOOKUP(C2624,Hoja1!$B$2:$B$6191,Hoja1!$A$2:$A$6191),VLOOKUP(C2624,Hoja1!$B$1:$C$6191,2,0)),"No esta en Infor") -> NAC0618 | C2624: Cal Coast Orchids | D2624: 0 | F2624: 120.02 | G2624: 0 | H2624: 0 | I2624: 0 | J2624: =SUM(D2624:I2624) -> 120.02
A2625: 45565 | B2625: =IFERROR(IF(VLOOKUP(C2625,Hoja1!$B$1:$C$6191,2,0)="",_xlfn.XLOOKUP(C2625,Hoja1!$B$2:$B$6191,Hoja1!$A$2:$A$6191),VLOOKUP(C2625,Hoja1!$B$1:$C$6191,2,0)),"No esta en Infor") -> CAN0011 | C2625: CosMic Plants | D2625: 589.86 | F2625: 2709.74 | G2625: 381.94 | H2625: 0 | I2625: 0 | J2625: =SUM(D2625:I2625) -> 3681.54
A2626: 45565 | B2626: =IFERROR(IF(VLOOKUP(C2626,Hoja1!$B$1:$C$6191,2,0)="",_xlfn.XLOOKUP(C2626,Hoja1!$B$2:$B$6191,Hoja1!$A$2:$A$6191),VLOOKUP(C2626,Hoja1!$B$1:$C$6191,2,0)),"No esta en Infor") -> NAC0673 | C2626: Cottage Flowers, Inc | D2626: 0 | F2626: 0 | G2626: 32.73 | H2626: 0 | I2626: 0 | J2626: =SUM(D2626:I2626) -> 32.73
A2627: 45565 | B2627: =IFERROR(IF(VLOOKUP(C2627,Hoja1!$B$1:$C$6191,2,0)="",_xlfn.XLOOKUP(C2627,Hoja1!$B$2:$B$6191,Hoja1!$A$2:$A$6191),VLOOKUP(C2627,Hoja1!$B$1:$C$6191,2,0)),"No esta en Infor") -> NAC0729 | C2627: Downs Wholesale* | D2627: 0 | F2627: 0 | G2627: 316 | H2627: 0 | I2627: 0 | J2627: =SUM(D2627:I2627) -> 316
A2628: 45565 | B2628: =IFERROR(IF(VLOOKUP(C2628,Hoja1!$B$1:$C$6191,2,0)="",_xlfn.XLOOKUP(C2628,Hoja1!$B$2:$B$6191,Hoja1!$A$2:$A$6191),VLOOKUP(C2628,Hoja1!$B$1:$C$6191,2,0)),"No esta en Infor") -> NAC0734 | C2628: Dube's Flower Shop | D2628: 311.66 | F2628: 235.64 | G2628: 0 | H2628: 0 | I2628: 0 | J2628: =SUM(D2628:I2628) -> 547.3
A2629: 45565 | B2629: =IFERROR(IF(VLOOKUP(C2629,Hoja1!$B$1:$C$6191,2,0)="",_xlfn.XLOOKUP(C2629,Hoja1!$B$2:$B$6191,Hoja1!$A$2:$A$6191),VLOOKUP(C2629,Hoja1!$B$1:$C$6191,2,0)),"No esta en Infor") -> CAN0018 | C2629: Fleurs et Passion Yasmina | D2629: 22513.6 | F2629: 41166.72 | G2629: 0 | H2629: 3809.19 | I2629: 0 | J2629: =SUM(D2629:I2629) -> 67489.51
... A3688: 45626 | B3688: =IFERROR(IF(VLOOKUP(C3688,Hoja1!$B$1:$C$6191,2,0)="",_xlfn.XLOOKUP(C3688,Hoja1!$B$2:$B$6191,Hoja1!$A$2:$A$6191),VLOOKUP(C3688,Hoja1!$B$1:$C$6191,2,0)),"No esta en Infor") -> NAC1539 | C3688: Young's Plant Farm, Inc | D3688: 2636.8 | F3688: 0 | G3688: 0 | H3688: 0 | I3688: 0 | J3688: =SUM(D3688:I3688) -> 2636.8
A3689: 45657 | B3689: =IFERROR(IF(VLOOKUP(C3689,Hoja1!$B$1:$C$6191,2,0)="",_xlfn.XLOOKUP(C3689,Hoja1!$B$2:$B$6191,Hoja1!$A$2:$A$6191),VLOOKUP(C3689,Hoja1!$B$1:$C$6191,2,0)),"No esta en Infor") -> NAC0476 | C3689: Ahold USA | D3689: 239837.44 | F3689: 49.81 | G3689: 774.08 | H3689: 2250 | I3689: -345.39 | J3689: =SUM(E3689:I3689) -> 2728.5
A3690: 45657 | B3690: =IFERROR(IF(VLOOKUP(C3690,Hoja1!$B$1:$C$6191,2,0)="",_xlfn.XLOOKUP(C3690,Hoja1!$B$2:$B$6191,Hoja1!$A$2:$A$6191),VLOOKUP(C3690,Hoja1!$B$1:$C$6191,2,0)),"No esta en Infor") -> NAC0483 | C3690: Albertsons | D3690: 0 | F3690: -146.83 | G3690: 0 | H3690: 0 | I3690: 474.11 | J3690: =SUM(E3690:I3690) -> 327.28
A3691: 45657 | B3691: =IFERROR(IF(VLOOKUP(C3691,Hoja1!$B$1:$C$6191,2,0)="",_xlfn.XLOOKUP(C3691,Hoja1!$B$2:$B$6191,Hoja1!$A$2:$A$6191),VLOOKUP(C3691,Hoja1!$B$1:$C$6191,2,0)),"No esta en Infor") -> CAN0002 | C3691: Bayview Flowers | D3691: 4991.49 | F3691: 0 | G3691: 0 | H3691: -804.19 | I3691: 249.72 | J3691: =SUM(E3691:I3691) -> -554.47
A3692: 45657 | B3692: =IFERROR(IF(VLOOKUP(C3692,Hoja1!$B$1:$C$6191,2,0)="",_xlfn.XLOOKUP(C3692,Hoja1!$B$2:$B$6191,Hoja1!$A$2:$A$6191),VLOOKUP(C3692,Hoja1!$B$1:$C$6191,2,0)),"No esta en Infor") -> NAC0573 | C3692: BFG SUPPLY COMPANY | D3692: 15467.3 | F3692: 254 | G3692: 0 | H3692: 0 | I3692: 283.5 | J3692: =SUM(E3692:I3692) -> 537.5
A3693: 45657 | B3693: =IFERROR(IF(VLOOKUP(C3693,Hoja1!$B$1:$C$6191,2,0)="",_xlfn.XLOOKUP(C3693,Hoja1!$B$2:$B$6191,Hoja1!$A$2:$A$6191),VLOOKUP(C3693,Hoja1!$B$1:$C$6191,2,0)),"No esta en Infor") -> CAN0006 | C3693: Burnaby Lake Greenhouses | D3693: 22184.4 | F3693: 893.02 | G3693: 0 | H3693: -1036.68 | I3693: 0 | J3693: =SUM(E3693:I3693) -> -143.66
A3694: 45657 | B3694: =IFERROR(IF(VLOOKUP(C3694,Hoja1!$B$1:$C$6191,2,0)="",_xlfn.XLOOKUP(C3694,Hoja1!$B$2:$B$6191,Hoja1!$A$2:$A$6191),VLOOKUP(C3694,Hoja1!$B$1:$C$6191,2,0)),"No esta en Infor") -> NAC0614 | C3694: C&S Wholesale Grocers | D3694: 8621.5 | F3694: 29.44 | G3694: 0 | H3694: 0 | I3694: 0 | J3694: =SUM(E3694:I3694) -> 29.44
A3695: 45657 | B3695: =IFERROR(IF(VLOOKUP(C3695,Hoja1!$B$1:$C$6191,2,0)="",_xlfn.XLOOKUP(C3695,Hoja1!$B$2:$B$6191,Hoja1!$A$2:$A$6191),VLOOKUP(C3695,Hoja1!$B$1:$C$6191,2,0)),"No esta en Infor") -> NAC0618 | C3695: Cal Coast Orchids | D3695: 0 | F3695: 0 | G3695: 120.02 | H3695: 0 | I3695: 0 | J3695: =SUM(E3695:I3695) -> 120.02
A3696: 45657 | B3696: =IFERROR(IF(VLOOKUP(C3696,Hoja1!$B$1:$C$6191,2,0)="",_xlfn.XLOOKUP(C3696,Hoja1!$B$2:$B$6191,Hoja1!$A$2:$A$6191),VLOOKUP(C3696,Hoja1!$B$1:$C$6191,2,0)),"No esta en Infor") -> CAN0011 | C3696: CosMic Plants | D3696: 6902.22 | F3696: 0 | G3696: 2709.74 | H3696: 381.94 | I3696: 0 | J3696: =SUM(E3696:I3696) -> 3091.68
A3697: 45657 | B3697: =IFERROR(IF(VLOOKUP(C3697,Hoja1!$B$1:$C$6191,2,0)="",_xlfn.XLOOKUP(C3697,Hoja1!$B$2:$B$6191,Hoja1!$A$2:$A$6191),VLOOKUP(C3697,Hoja1!$B$1:$C$6191,2,0)),"No esta en Infor") -> NAC0672 | C3697: Costa Farms | D3697: 11448.34 | F3697: 8878 | G3697: 0 | H3697: 0 | I3697: 0 | J3697: =SUM(E3697:I3697) -> 8878
A3698: 45657 | B3698: =IFERROR(IF(VLOOKUP(C3698,Hoja1!$B$1:$C$6191,2,0)="",_xlfn.XLOOKUP(C3698,Hoja1!$B$2:$B$6191,Hoja1!$A$2:$A$6191),VLOOKUP(C3698,Hoja1!$B$1:$C$6191,2,0)),"No esta en Infor") -> NAC0673 | C3698: Cottage Flowers, Inc | D3698: 982.62 | F3698: 0 | G3698: 0 | H3698: 32.73 | I3698: 0 | J3698: =SUM(E3698:I3698) -> 32.73
A3699: 45657 | B3699: =IFERROR(IF(VLOOKUP(C3699,Hoja1!$B$1:$C$6191,2,0)="",_xlfn.XLOOKUP(C3699,Hoja1!$B$2:$B$6191,Hoja1!$A$2:$A$6191),VLOOKUP(C3699,Hoja1!$B$1:$C$6191,2,0)),"No esta en Infor") -> NAC0729 | C3699: Downs Wholesale* | D3699: 0 | F3699: 0 | G3699: 0 | H3699: 316 | I3699: 0 | J3699: =SUM(E3699:I3699) -> 316
A3700: 45657 | B3700: =IFERROR(IF(VLOOKUP(C3700,Hoja1!$B$1:$C$6191,2,0)="",_xlfn.XLOOKUP(C3700,Hoja1!$B$2:$B$6191,Hoja1!$A$2:$A$6191),VLOOKUP(C3700,Hoja1!$B$1:$C$6191,2,0)),"No esta en Infor") -> CAN0018 | C3700: Fleurs et Passion Yasmina | D3700: 24559.14 | F3700: 0 | G3700: 21588.88 | H3700: 0 | I3700: 0 | J3700: =SUM(E3700:I3700) -> 21588.88
... A4022: 45657 | B4022: =IFERROR(IF(VLOOKUP(C4022,Hoja1!$B$1:$C$6191,2,0)="",_xlfn.XLOOKUP(C4022,Hoja1!$B$2:$B$6191,Hoja1!$A$2:$A$6191),VLOOKUP(C4022,Hoja1!$B$1:$C$6191,2,0)),"No esta en Infor") -> NAC1530 | C4022: Woodlane Flowers, Inc. | D4022: -0.01 | F4022: 0 | G4022: 0 | H4022: 0 | I4022: 0 | J4022: =SUM(E4022:I4022) -> 0
...

Sheet Write off
A1: Sequence | B1: Account | C1: Account Description | D1: Date | E1: Site | F1: Debit (Domestic) | G1: Credit (Domestic) | H1: Exchange Rate | I1: Debit (Foreign) | J1: Credit (Foreign) | L1: REFERENCE | M1: Allocation Transaction | N1: Posted From | O1: Posted From Site | P1: G/L Voucher | Q1: Approver | R1: Cust/Vendor | S1: Name | T1: Invoice/Voucher | U1: Cancellation | V1: Invoice/Vch Seq | W1: Hierarchy | X1: Control Prefix | Y1: Control Site | Z1: Control Year | AA1: Control Period | AB1: Control Number | AC1: Ref Control Prefix | AD1: Ref Control Site | AE1: Ref Control Year | AF1: Ref Control Period | AG1: Ref Control Number | AH1: Document Number | AI1: Check# | AJ1: Check Date | AK1: Currency | AL1: Bank Code | AM1: Consolidated | AN1: Date | AO1: Nº artículo | AP1: Descripción Item | AQ1: Cantidad | AR1: Item (Manual) | AS1: Item Description (manual) | AT1: Analysis Attribute 6 | AU1: Analysis Attribute 7 | AV1: Analysis Attribute 8 | AW1: Analysis Attribute 9 | AX1: Analysis Attribute 10 | AY1: Analysis Attribute 11 | AZ1: Analysis Attribute 12 | BA1: Analysis Attribute 13 | BB1: Analysis Attribute 14 | BC1: Analysis Attribute 15 | BD1: Analysis Attribute 15 | BE1: Analysis Attribute 15 | BF1: Ajuste | BG1: Fecha de Ajuste
A2: 384 | B2: 13990002 | C2: Bad Debt reserve | D2: 45532 | E2: SHGI | F2: 0 | G2: 157985.21 | H2: 1 | I2: 0 | J2: 157985.21 | K2: =J2-I2 -> 157985.21 | L2: Opening Balance | N2: OBS Dist | T2: 0 | U2: 0 | V2: 0 | X2: OB | Y2: SHGI | Z2: 2024 | AA2: 8 | AB2: 1 | AC2: OB | AD2: SHGI | AE2: 2024 | AF2: 8 | AG2: 1 | AI2: 0 | AK2: USD | AM2: Yes
A3: 5054 | B3: 13990002 | C3: Bad Debt reserve | D3: 45535 | E3: SHGI | F3: 0 | G3: 766.69 | H3: 1 | I3: 0 | J3: 766.69 | K3: =J3-I3 -> 766.69 | L3: Accrual A/R August 2024 | N3: General | T3: 0 | U3: 0 | V3: 0 | X3: GE | Y3: SHGI | Z3: 2024 | AA3: 8 | AB3: 1 | AC3: GE | AD3: SHGI | AE3: 2024 | AF3: 8 | AG3: 1 | AI3: 0 | AK3: USD | AM3: Yes
A4: 25744 | B4: 13990002 | C4: Bad Debt reserve | D4: 45573 | E4: SHGI | F4: 59358.88 | G4: 0 | H4: 1 | I4: 59358.88 | J4: 0 | K4: =J4-I4 -> -59358.88 | L4: Provision HH - Sept 2024 | N4: General | T4: 0 | U4: 0 | V4: 0 | X4: GE | Y4: SHGI | Z4: 2024 | AA4: 10 | AB4: 2 | AC4: GE | AD4: SHGI | AE4: 2024 | AF4: 10 | AG4: 2 | AI4: 0 | AK4: USD | AM4: Yes
A5: 47327 | B5: 13990002 | C5: Bad Debt reserve | D5: 45596 | E5: SHGI | F5: 0 | G5: 24158.11 | H5: 1 | I5: 0 | J5: 24158.11 | K5: =J5-I5 -> 24158.11 | L5: Ajuste Provision Sep 2024 | N5: General | T5: 0 | U5: 0 | V5: 0 | X5: GE | Y5: SHGI | Z5: 2024 | AA5: 10 | AB5: 4 | AC5: GE | AD5: SHGI | AE5: 2024 | AF5: 10 | AG5: 4 | AI5: 0 | AK5: USD | AM5: Yes
A6: 47329 | B6: 13990002 | C6: Bad Debt reserve | D6: 45596 | E6: SHGI | F6: 8670.62 | G6: 0 | H6: 1 | I6: 8670.62 | J6: 0 | K6: =J6-I6 -> -8670.62 | L6: Regsitro Provision Oct 2024 | N6: General | T6: 0 | U6: 0 | V6: 0 | X6: GE | Y6: SHGI | Z6: 2024 | AA6: 10 | AB6: 4 | AC6: GE | AD6: SHGI | AE6: 2024 | AF6: 10 | AG6: 4 | AI6: 0 | AK6: USD | AM6: Yes
A7: 72792 | B7: 13990002 | C7: Bad Debt reserve | D7: 45626 | E7: SHGI | F7: 6246.41 | G7: 0 | H7: 1 | I7: 6246.41 | J7: 0 | K7: =J7-I7 -> -6246.41 | L7: Registro Provision Nov 2024 | N7: General | T7: 0 | U7: 0 | V7: 0 | X7: GE | Y7: SHGI | Z7: 2024 | AA7: 11 | AB7: 1 | AC7: GE | AD7: SHGI | AE7: 2024 | AF7: 11 | AG7: 1 | AI7: 0 | AK7: USD | AM7: Yes
A8: 93647 | B8: 13990002 | C8: Bad Debt reserve | D8: 45657 | E8: SHGI | F8: 0 | G8: 22267.79 | H8: 1 | I8: 0 | J8: 22267.79 | K8: =J8-I8 -> 22267.79 | L8: Registro provision Dic | N8: General | T8: 0 | U8: 0 | V8: 0 | X8: GE | Y8: SHGI | Z8: 2024 | AA8: 12 | AB8: 4 | AC8: GE | AD8: SHGI | AE8: 2024 | AF8: 12 | AG8: 4 | AI8: 0 | AK8: USD | AM8: Yes
A9: 122540 | B9: 13990002 | C9: Bad Debt reserve | D9: 45688 | E9: SHGI | F9: 75.01 | G9: 0 | H9: 1 | I9: 75.01 | J9: 0 | K9: =J9-I9 -> -75.01 | L9: Registro Prov Ene 2025 | N9: General | T9: 0 | U9: 0 | V9: 0 | X9: GE | Y9: SHGI | Z9: 2025 | AA9: 1 | AB9: 1 | AC9: GE | AD9: SHGI | AE9: 2025 | AF9: 1 | AG9: 1 | AI9: 0 | AK9: USD | AM9: Yes | BF9: Ajuste | BG9: 45808
A10: 140539 | B10: 13990002 | C10: Bad Debt reserve | D10: 45657 | E10: SHGI | F10: 138828.43 | G10: 0 | H10: 1 | I10: 138828.43 | J10: 0 | K10: =J10-I10 -> -138828.43 | L10: Perdida esperada reserve 2024 | N10: CT Dist | T10: 0 | U10: 0 | V10: 0 | X10: CT | Y10: SHGI | Z10: 2024 | AA10: 12 | AB10: 68 | AC10: CT | AD10: SHGI | AE10: 2024 | AF10: 12 | AG10: 68 | AI10: 0 | AK10: USD | AM10: Yes
A11: 140637 | B11: 13990002 | C11: Bad Debt reserve | D11: 45657 | E11: SHGI | F11: 0 | G11: 138828.43 | H11: 1 | I11: 0 | J11: 138828.43 | K11: =J11-I11 -> 138828.43 | L11: Perdida esperada reserve 2024 | N11: CT Dist | T11: 0 | U11: 0 | V11: 0 | X11: CT | Y11: SHGI | Z11: 2024 | AA11: 12 | AB11: 69 | AC11: CT | AD11: SHGI | AE11: 2024 | AF11: 12 | AG11: 69 | AI11: 0 | AK11: USD | AM11: Yes
A12: 140639 | B12: 13990002 | C12: Bad Debt reserve | D12: 45657 | E12: SHGI | F12: 0 | G12: 7926.54 | H12: 1 | I12: 0 | J12: 7926.54 | K12: =J12-I12 -> 7926.54 | L12: Perdida esperada reserve 2024 | N12: CT Dist | T12: 0 | U12: 0 | V12: 0 | X12: CT | Y12: SHGI | Z12: 2024 | AA12: 12 | AB12: 70 | AC12: CT | AD12: SHGI | AE12: 2024 | AF12: 12 | AG12: 70 | AI12: 0 | AK12: USD | AM12: Yes
A13: 140641 | B13: 13990002 | C13: Bad Debt reserve | D13: 45688 | E13: SHGI | F13: 2897.36 | G13: 0 | H13: 1 | I13: 2897.36 | J13: 0 | K13: =J13-I13 -> -2897.36 | L13: Perdida esperada reserve 2025 | N13: CT Dist | T13: 0 | U13: 0 | V13: 0 | X13: CT | Y13: SHGI | Z13: 2025 | AA13: 1 | AB13: 49 | AC13: CT | AD13: SHGI | AE13: 2025 | AF13: 1 | AG13: 49 | AI13: 0 | AK13: USD | AM13: Yes
A14: 156971 | B14: 13990002 | C14: Bad Debt reserve | D14: 45716 | E14: SHGI | F14: 0 | G14: 2184.79 | H14: 1 | I14: 0 | J14: 2184.79 | K14: =J14-I14 -> 2184.79 | L14: Provision CECL Feb | N14: General | T14: 0 | U14: 0 | V14: 0 | X14: GE | Y14: SHGI | Z14: 2025 | AA14: 2 | AB14: 1 | AC14: GE | AD14: SHGI | AE14: 2025 | AF14: 2 | AG14: 1 | AI14: 0 | AK14: USD | AM14: Yes
A15: 156974 | B15: 13990002 | C15: Bad Debt reserve | D15: 45716 | E15: SHGI | F15: 0 | G15: 75.1 | H15: 1 | I15: 0 | J15: 75.1 | K15: =J15-I15 -> 75.1 | L15: Provision CECL Feb Ajuste ENE | N15: General | T15: 0 | U15: 0 | V15: 0 | X15: GE | Y15: SHGI | Z15: 2025 | AA15: 2 | AB15: 1 | AC15: GE | AD15: SHGI | AE15: 2025 | AF15: 2 | AG15: 1 | AI15: 0 | AK15: USD | AM15: Yes | BF15: Ajuste | BG15: 45808
A16: 173295 | B16: 13990002 | C16: Bad Debt reserve | D16: 45736 | E16: SHGI | F16: 120.02 | G16: 0 | H16: 1 | I16: 120.02 | J16: 0 | K16: =J16-I16 -> -120.02 | L16: ARP 32025-Write off-Mauro3-20 | N16: CA Dist | R16: NAC0618 | T16: 0 | U16: 0 | V16: 0 | X16: CA | Y16: SHGI | Z16: 2025 | AA16: 3 | AB16: 1 | AC16: CA | AD16: SHGI | AE16: 2025 | AF16: 3 | AG16: 1 | AI16: 0 | AK16: USD | AM16: Yes | BF16: Ajuste | BG16: 45808
A17: 187698 | B17: 13990002 | C17: Bad Debt reserve | D17: 45747 | E17: SHGI | F17: 0 | G17: 6303.2 | H17: 1 | I17: 0 | J17: 6303.2 | K17: =J17-I17 -> 6303.2 | L17: Provision Mar 2025 | N17: General | R17: INT0060 | T17: 0 | U17: 0 | V17: 0 | X17: GE | Y17: SHGI | Z17: 2025 | AA17: 3 | AB17: 1 | AC17: GE | AD17: SHGI | AE17: 2025 | AF17: 3 | AG17: 1 | AI17: 0 | AK17: USD | AM17: Yes
A18: 222428 | B18: 13990002 | C18: Bad Debt reserve | D18: 45777 | E18: SHGI | F18: 0 | G18: 9258.66 | H18: 1 | I18: 0 | J18: 9258.66 | K18: =J18-I18 -> 9258.66 | L18: Provision Abril 2025 | N18: General | R18: INT0060 | T18: 0 | U18: 0 | V18: 0 | X18: GE | Y18: SHGI | Z18: 2025 | AA18: 4 | AB18: 1 | AC18: GE | AD18: SHGI | AE18: 2025 | AF18: 4 | AG18: 1 | AI18: 0 | AK18: USD | AM18: Yes
A19: 227971 | B19: 13990002 | C19: Bad Debt reserve | D19: 45790 | E19: SHGI | F19: 9360 | G19: 0 | H19: 1 | I19: 9360 | J19: 0 | K19: =J19-I19 -> -9360 | L19: ARP 123-Write off-Steven 5-13 | N19: AR Dist | O19: SHGI | R19: NAC0988 | S19: Jewel Foods Stores | T19: HGI0115442 | U19: 0 | V19: 123 | X19: AR | Y19: SHGI | Z19: 2025 | AA19: 5 | AB19: 692 | AC19: AR | AD19: SHGI | AE19: 2025 | AF19: 5 | AG19: 692 | AI19: 123 | AJ19: 45790 | AK19: USD | AL19: 686 | AM19: Yes
A20: 246946 | B20: 13990002 | C20: Bad Debt reserve | D20: 45808 | E20: SHGI | F20: 450 | G20: 0 | H20: 1 | I20: 450 | J20: 0 | K20: =J20-I20 -> -450 | L20: ARP 53125-WriteOff-Julian 6-4 | N20: AR Dist | O20: SHGI | R20: NAC0476 | S20: Ahold USA | T20: HGI0121188 | U20: 0 | V20: 53125 | X20: AR | Y20: SHGI | Z20: 2025 | AA20: 5 | AB20: 2016 | AC20: AR | AD20: SHGI | AE20: 2025 | AF20: 5 | AG20: 2016 | AI20: 53125 | AJ20: 45808 | AK20: USD | AL20: 686 | AM20: Yes
A21: 246948 | B21: 13990002 | C21: Bad Debt reserve | D21: 45808 | E21: SHGI | F21: 300 | G21: 0 | H21: 1 | I21: 300 | J21: 0 | K21: =J21-I21 -> -300 | L21: ARP 53125-WriteOff-Julian 6-4 | N21: AR Dist | O21: SHGI | R21: NAC1448 | S21: UNFI | T21: HGI0119260 | U21: 0 | V21: 53125 | X21: AR | Y21: SHGI | Z21: 2025 | AA21: 5 | AB21: 2017 | AC21: AR | AD21: SHGI | AE21: 2025 | AF21: 5 | AG21: 2017 | AI21: 53125 | AJ21: 45808 | AK21: USD | AL21: 686 | AM21: Yes
A22: 246950 | B22: 13990002 | C22: Bad Debt reserve | D22: 45808 | E22: SHGI | F22: 325 | G22: 0 | H22: 1 | I22: 325 | J22: 0 | K22: =J22-I22 -> -325 | L22: ARP 53125-WriteOff-Julian 6-4 | N22: AR Dist | O22: SHGI | R22: NAC1322 | S22: Safeway Northern CA | T22: HGI0126246 | U22: 0 | V22: 53125 | X22: AR | Y22: SHGI | Z22: 2025 | AA22: 5 | AB22: 2018 | AC22: AR | AD22: SHGI | AE22: 2025 | AF22: 5 | AG22: 2018 | AI22: 53125 | AJ22: 45808 | AK22: USD | AL22: 686 | AM22: Yes
A23: 246953 | B23: 13990002 | C23: Bad Debt reserve | D23: 45808 | E23: SHGI | F23: 15.54 | G23: 0 | H23: 1 | I23: 15.54 | J23: 0 | K23: =J23-I23 -> -15.54 | L23: ARP 53125-WriteOff-Julian 6-4 | N23: AR Dist | O23: SHGI | R23: NAC1327 | S23: Sam's Club- | T23: HGI0125912 | U23: 0 | V23: 53125 | X23: AR | Y23: SHGI | Z23: 2025 | AA23: 5 | AB23: 2019 | AC23: AR | AD23: SHGI | AE23: 2025 | AF23: 5 | AG23: 2019 | AI23: 53125 | AJ23: 45808 | AK23: USD | AL23: 686 | AM23: Yes
A24: 246956 | B24: 13990002 | C24: Bad Debt reserve | D24: 45808 | E24: SHGI | F24: 31.08 | G24: 0 | H24: 1 | I24: 31.08 | J24: 0 | K24: =J24-I24 -> -31.08 | L24: ARP 53125-WriteOff-Julian 6-4 | N24: AR Dist | O24: SHGI | R24: NAC1327 | S24: Sam's Club- | T24: HGI0125914 | U24: 0 | V24: 53125 | X24: AR | Y24: SHGI | Z24: 2025 | AA24: 5 | AB24: 2019 | AC24: AR | AD24: SHGI | AE24: 2025 | AF24: 5 | AG24: 2019 | AI24: 53125 | AJ24: 45808 | AK24: USD | AL24: 686 | AM24: Yes
A25: 246959 | B25: 13990002 | C25: Bad Debt reserve | D25: 45808 | E25: SHGI | F25: 31.08 | G25: 0 | H25: 1 | I25: 31.08 | J25: 0 | K25: =J25-I25 -> -31.08 | L25: ARP 53125-WriteOff-Julian 6-4 | N25: AR Dist | O25: SHGI | R25: NAC1327 | S25: Sam's Club- | T25: HGI0126669 | U25: 0 | V25: 53125 | X25: AR | Y25: SHGI | Z25: 2025 | AA25: 5 | AB25: 2019 | AC25: AR | AD25: SHGI | AE25: 2025 | AF25: 5 | AG25: 2019 | AI25: 53125 | AJ25: 45808 | AK25: USD | AL25: 686 | AM25: Yes
A26: 247820 | B26: 13990002 | C26: Bad Debt reserve | D26: 45808 | E26: SHGI | F26: 0 | G26: 10057.22 | H26: 1 | I26: 0 | J26: 10057.22 | K26: =J26-I26 -> 10057.22 | L26: Provision Mayo 2025 | N26: General | R26: INT0060 | T26: 0 | U26: 0 | V26: 0 | X26: GE | Y26: SHGI | Z26: 2025 | AA26: 5 | AB26: 1 | AC26: GE | AD26: SHGI | AE26: 2025 | AF26: 5 | AG26: 1 | AI26: 0 | AK26: USD | AM26: Yes
A27: 265139 | B27: 13990002 | C27: Bad Debt reserve | D27: 45838 | E27: SHGI | F27: 0 | G27: 9146.56 | H27: 1 | I27: 0 | J27: 9146.56 | K27: =J27-I27 -> 9146.56 | L27: Provision Junio 2025 | N27: General | R27: INT0060 | T27: 0 | U27: 0 | V27: 0 | X27: GE | Y27: SHGI | Z27: 2025 | AA27: 6 | AB27: 1 | AC27: GE | AD27: SHGI | AE27: 2025 | AF27: 6 | AG27: 1 | AI27: 0 | AK27: USD | AM27: Yes
A28: 272514 | B28: 13990002 | C28: Bad Debt reserve | D28: 45852 | E28: SHGI | F28: 3488 | G28: 0 | H28: 1 | I28: 3488 | J28: 0 | K28: =J28-I28 -> -3488 | L28: ARP 71425-WriteOff-Mauro07-07 | N28: AR Dist | O28: SHGI | R28: NAC0988 | S28: Jewel Foods Stores | T28: INV0001154 | U28: 0 | V28: 71425 | X28: AR | Y28: SHGI | Z28: 2025 | AA28: 7 | AB28: 533 | AC28: AR | AD28: SHGI | AE28: 2025 | AF28: 7 | AG28: 533 | AI28: 71425 | AJ28: 45852 | AK28: USD | AL28: 686 | AM28: Yes
A29: 288655 | B29: 13990002 | C29: Bad Debt reserve | D29: 45869 | E29: SHGI | F29: 0 | G29: 10894.39 | H29: 1 | I29: 0 | J29: 10894.39 | K29: =J29-I29 -> 10894.39 | L29: Provision Julio 2025 | N29: General | R29: INT0060 | T29: 0 | U29: 0 | V29: 0 | X29: GE | Y29: SHGI | Z29: 2025 | AA29: 7 | AB29: 1 | AC29: GE | AD29: SHGI | AE29: 2025 | AF29: 7 | AG29: 1 | AI29: 0 | AK29: USD | AM29: Yes
A30: 319962 | B30: 13990002 | C30: Bad Debt reserve | D30: 45900 | E30: SHGI | F30: 8309.19 | G30: 0 | H30: 1 | I30: 8309.19 | J30: 0 | K30: =J30-I30 -> -8309.19 | L30: Provision Agosto 2025 | N30: General | R30: INT0060 | T30: 0 | U30: 0 | V30: 0 | X30: GE | Y30: SHGI | Z30: 2025 | AA30: 8 | AB30: 1 | AC30: GE | AD30: SHGI | AE30: 2025 | AF30: 8 | AG30: 1 | AI30: 0 | AK30: USD | AM30: Yes
A31: 320027 | B31: 13990002 | C31: Bad Debt reserve | D31: 45900 | E31: SHGI | F31: 0 | G31: 1363.27 | H31: 1 | I31: 0 | J31: 1363.27 | K31: =J31-I31 -> 1363.27 | L31: Ajuste Provision Agosto 2025 | N31: General | R31: INT0060 | T31: 0 | U31: 0 | V31: 0 | X31: GE | Y31: SHGI | Z31: 2025 | AA31: 8 | AB31: 2 | AC31: GE | AD31: SHGI | AE31: 2025 | AF31: 8 | AG31: 2 | AI31: 0 | AK31: USD | AM31: Yes
A32: 340554 | B32: 13990002 | C32: Bad Debt reserve | D32: 45929 | E32: SHGI | F32: 500 | G32: 0 | H32: 1 | I32: 500 | J32: 0 | K32: =J32-I32 -> -500 | L32: ARP 1234-WriteOff-Adolfo 9-28 | N32: AR Dist | O32: SHGI | R32: NAC0988 | S32: Jewel Foods Stores | T32: INV0002621 | U32: 0 | V32: 1234 | X32: AR | Y32: SHGI | Z32: 2025 | AA32: 9 | AB32: 1598 | AC32: AR | AD32: SHGI | AE32: 2025 | AF32: 9 | AG32: 1598 | AI32: 1234 | AJ32: 45929 | AK32: USD | AL32: 686 | AM32: No
A33: 340556 | B33: 13990002 | C33: Bad Debt reserve | D33: 45929 | E33: SHGI | F33: 1408.12 | G33: 0 | H33: 1 | I33: 1408.12 | J33: 0 | K33: =J33-I33 -> -1408.12 | L33: ARP 1234-WriteOff-Adolfo 9-28 | N33: AR Dist | O33: SHGI | R33: NAC1035 | S33: Kroger Peyton's Mid South | T33: INV0003977 | U33: 0 | V33: 1234 | X33: AR | Y33: SHGI | Z33: 2025 | AA33: 9 | AB33: 1599 | AC33: AR | AD33: SHGI | AE33: 2025 | AF33: 9 | AG33: 1599 | AI33: 1234 | AJ33: 45929 | AK33: USD | AL33: 686 | AM33: No
A34: 340558 | B34: 13990002 | C34: Bad Debt reserve | D34: 45929 | E34: SHGI | F34: 649.3 | G34: 0 | H34: 1 | I34: 649.3 | J34: 0 | K34: =J34-I34 -> -649.3 | L34: ARP 1234-WriteOff-Adolfo 9-28 | N34: AR Dist | O34: SHGI | R34: NAC1322 | S34: Safeway Northern CA | T34: HGI0119907 | U34: 0 | V34: 1234 | X34: AR | Y34: SHGI | Z34: 2025 | AA34: 9 | AB34: 1600 | AC34: AR | AD34: SHGI | AE34: 2025 | AF34: 9 | AG34: 1600 | AI34: 1234 | AJ34: 45929 | AK34: USD | AL34: 686 | AM34: No
A35: 340560 | B35: 13990002 | C35: Bad Debt reserve | D35: 45929 | E35: SHGI | F35: 1988.1 | G35: 0 | H35: 1 | I35: 1988.1 | J35: 0 | K35: =J35-I35 -> -1988.1 | L35: ARP 1234-WriteOff-Adolfo 9-28 | N35: AR Dist | O35: SHGI | R35: NAC1316 | S35: Safeway Southern CA | T35: HGI0125791 | U35: 0 | V35: 1234 | X35: AR | Y35: SHGI | Z35: 2025 | AA35: 9 | AB35: 1600 | AC35: AR | AD35: SHGI | AE35: 2025 | AF35: 9 | AG35: 1600 | AI35: 1234 | AJ35: 45929 | AK35: USD | AL35: 686 | AM35: No
A36: 340562 | B36: 13990002 | C36: Bad Debt reserve | D36: 45929 | E36: SHGI | F36: 1647.24 | G36: 0 | H36: 1 | I36: 1647.24 | J36: 0 | K36: =J36-I36 -> -1647.24 | L36: ARP 1234-WriteOff-Adolfo 9-28 | N36: AR Dist | O36: SHGI | R36: NAC1327 | S36: Sam's Club- | T36: HGI0124508 | U36: 0 | V36: 1234 | X36: AR | Y36: SHGI | Z36: 2025 | AA36: 9 | AB36: 1601 | AC36: AR | AD36: SHGI | AE36: 2025 | AF36: 9 | AG36: 1601 | AI36: 1234 | AJ36: 45929 | AK36: USD | AL36: 686 | AM36: No
A37: 340564 | B37: 13990002 | C37: Bad Debt reserve | D37: 45929 | E37: SHGI | F37: 264 | G37: 0 | H37: 1 | I37: 264 | J37: 0 | K37: =J37-I37 -> -264 | L37: ARP 1234-WriteOff-Adolfo 9-28 | N37: AR Dist | O37: SHGI | R37: NAC1327 | S37: Sam's Club- | T37: HGI0125445 | U37: 0 | V37: 1234 | X37: AR | Y37: SHGI | Z37: 2025 | AA37: 9 | AB37: 1601 | AC37: AR | AD37: SHGI | AE37: 2025 | AF37: 9 | AG37: 1601 | AI37: 1234 | AJ37: 45929 | AK37: USD | AL37: 686 | AM37: No
A38: 340566 | B38: 13990002 | C38: Bad Debt reserve | D38: 45929 | E38: SHGI | F38: 500 | G38: 0 | H38: 1 | I38: 500 | J38: 0 | K38: =J38-I38 -> -500 | L38: ARP 1234-WriteOff-Adolfo 9-28 | N38: AR Dist | O38: SHGI | R38: NAC1318 | S38: Shaw´s Supermarket Inc. | T38: HGI0122285 | U38: 0 | V38: 1234 | X38: AR | Y38: SHGI | Z38: 2025 | AA38: 9 | AB38: 1602 | AC38: AR | AD38: SHGI | AE38: 2025 | AF38: 9 | AG38: 1602 | AI38: 1234 | AJ38: 45929 | AK38: USD | AL38: 686 | AM38: No

Sheet Indicadores Modelo Nuevo
B2: Banda de envejecimiento de pérdida esperada VIP
B3: Rangos de Maduracion | C3: Sin vencer-30 | D3: 31-90 | E3: 91-150 | F3: 151-240 | G3: 241+
B4: Saldos pendientes | C4: 26067416 | D4: Ventas que llegaron a la siguiente agrupación | E4: 26102871 | F4: 26088645 | G4: 35455.04
B5: Pérdidas a crédito | C5: 35455.04 | D5: 35455.04 | E5: 35455.04 | F5: 35455.04 | G5: 35455.04
B6: Total pérdida esperada | C6: 0.00091510618 | D6: 0.00094944625 | E6: 0.0015688807 | F6: 1 | G6: 1
B7: Tasa de incremento de 3.5% | C7: =C6*3.5% -> 3.2028716e-05 | D7: =D6*3.5% -> 3.3230619e-05 | E7: =E6*3.5% -> 5.4910823e-05 | F7: 0 | G7: 0
B8: Nueva tasa | C8: =C6+C7 -> 0.0009471349 | D8: =D6+D7 -> 0.00098267687 | E8: =E6+E7 -> 0.0016237915 | F8: =F6+F7 -> 1 | G8: =G6+G7 -> 1
B10: Banda de envejecimiento de pérdida esperada OTROS
B11: Rangos de Maduracion | C11: Sin vencer-30 | D11: 31-90 | E11: 91-150 | F11: 151-240 | G11: 241+
B12: Saldos pendientes | C12: 1.2292869e+08 | D12: 28281882 | E12: 9292427.9 | F12: 1408461.5 | G12: 250074.2
B13: Pérdidas a crédito | C13: 250074.2 | D13: 250074.2 | E13: 250074.2 | F13: 250074.2 | G13: 250074.2
B14: Total pérdida esperada | C14: 0.002034303 | D14: 0.0088422051 | E14: 0.026911611 | F14: 0.17755131 | G14: 1
B15: Tasa de incremento de 3.5% | C15: =C14*3.5% -> 7.1200605e-05 | D15: =D14*3.5% -> 0.00030947718 | E15: =E14*3.5% -> 0.00094190637 | F15: =F14*3.5% -> 0.006214296 | G15: 0
B16: Nueva tasa | C16: =C14+C15 -> 0.0021055036 | D16: =D14+D15 -> 0.0091516823 | E16: =E14+E15 -> 0.027853517 | F16: =F14+F15 -> 0.18376561 | G16: =G14+G15 -> 1
B20: VIP
B21: Ahold USA
B22: BUNZL
B23: Jewel Foods Stores
B24: Kroger
B25: Metro
B26: Publix Super Markets, Inc.
B27: Safeway
B28: Sam's Club-
B29: Supervalue
B30: UNFI
B31: Whole Foods Market
... B51: Americana Kingfisher co

Sheet Hoja1
A1: Customer | C1: Corporate Cust
A2: 1 | B2: THE GEMS GROUP MI
A3: CAN0001 | B3: Aldershot Greenhouses
A4: CAN0002 | B4: Bayview Flowers
A5: CAN0003 | B5: Bevo Farms, Ltd
A6: CAN0004 | B6: BH Flower Whole Sale Ltd
A7: CAN0005 | B7: Bloomstar Bouquet
A8: CAN0006 | B8: Burnaby Lake Greenhouses
A9: CAN0007 | B9: Central Botanical Growers
A10: CAN0008 | B10: Club Floral
A11: CAN0009 | B11: Colonial Florists LTD
A12: CAN0010 | B12: Comtois Fleurs Inc.
A13: CAN0011 | B13: CosMic Plants
A14: CAN0012 | B14: Costco Regional Office
... A71: CAN0069 | B71: Terra Greenhouses LTD
A72: CAN0070 | B72: The Flower Factory Winnipeg | C72: CAN0090
A73: CAN0071 | B73: The Flower Market
A74: CAN0072 | B74: Trillium Hill Greenhouses
A75: CAN0073 | B75: United Floral Distributors
A76: CAN0074 | B76: United Floral Inc.
A77: CAN0075 | B77: Valley Flowers Inc.-CN
A78: CAN0076 | B78: Van Geest Bros. Limited
A79: CAN0077 | B79: Vandermeer Greenhouses
A80: CAN0078 | B80: Vanderveen Greenhouse
A81: CAN0079 | B81: Vankampens Greenhouse
A82: CAN0080 | B82: Vermeer Greenhouses (Welland) Inc.
A83: CAN0081 | B83: Waldan Gardens
A84: CAN0082 | B84: Waterview Farms
... A86: CAN0084 | B86: Westland Greenhouses GB
A87: CAN0085 | B87: Whole Foods Canada 2 | C87: NAC1517
A88: CAN0086 | B88: Wild Stone Trading Co
A89: CAN0087 | B89: Willy s Greenhouses LTD
A90: CAN0088 | B90: Woodland Nurseries Ltd
A91: CAN0089 | B91: Bloomstar Bouquet Vancouver | C91: CAN0005
A92: CAN0090 | B92: The Flower Factory*
A93: CAN0091 | B93: Mainland Floral Distributors
A94: CAN0092 | B94: Gregory Greenhouses Inc
A95: CAN0093 | B95: Anna´s Garden, Home & Wellness
A96: CAN0094 | B96: Global Horticultural Inc.
A97: CAN0095 | B97: Farm to Canada
...
